  /**
   * Continues an observable sequence that is terminated by an exception with the next observable sequence.
   * @param ***REMOVED***Array | Arguments***REMOVED*** args Arguments or an array to use as the next sequence if an error occurs.
   * @returns ***REMOVED***Observable***REMOVED*** An observable sequence containing elements from consecutive source sequences until a source sequence terminates successfully.
   */
  var observableCatch = Observable.catchError = Observable['catch'] = function () ***REMOVED***
    return enumerableOf(argsOrArray(arguments, 0)).catchError();
  ***REMOVED***;

  /**
   * @deprecated use #catch or #catchError instead.
   */
  Observable.catchException = function () ***REMOVED***
    //deprecate('catchException', 'catch or catchError');
    return observableCatch.apply(null, arguments);
  ***REMOVED***;
